Workbook

Sheet Entities
A1: Parent | B1: Entity | C1: Description | D1: Properties | E1: DataType
B2: Control
A3: Control | B3: Asset
A4: Asset | B4: Access Control
A5: Asset | B5: Record
B6: Entity
B7: Organization
A8: Organization | B8: Policy | D8: ControlType | E8: int
D9: InformationSecurityProperties | E9: int[]
D10: CyberSecurityConcepts | E10: int[]
D11: OperationalCapabilities | E11: int[]
D12: SecurityDomains | E12: int[]
A14: Organization | B14: Procedure
A15: Organization | B15: Process
A16: Organization | B16: Rule
A17: Organization | B17: User
A18: User | B18: Device

Sheet Enums
A1: GroupId | B1: Name | C1: Id | D1: Active | F1: INSERT INTO asjrf517_ozorasoft_infoseccontrols.SystemParameters (group_id, id, name, active) VALUES
A2: 0 | B2: Control.Group | C2: 10 | D2: 1 | F2: =_xlfn.CONCAT("(",A2,", ",C2, ", '", B2, "', b'",D2,"'),") -> (0, 10, 'Control.Group', b'1'),
A3: 10 | B3: Organizational controls | C3: =C2+1 -> 11 | D3: 1 | F3: =_xlfn.CONCAT("(",A3,", ",C3, ", '", B3, "', b'",D3,"'),") -> (10, 11, 'Organizational controls', b'1'),
A4: 10 | B4: People controls | C4: =C3+1 -> 12 | D4: 1 | F4: =_xlfn.CONCAT("(",A4,", ",C4, ", '", B4, "', b'",D4,"'),") -> (10, 12, 'People controls', b'1'),
A5: 10 | B5: Physical controls | C5: =C4+1 -> 13 | D5: 1 | F5: =_xlfn.CONCAT("(",A5,", ",C5, ", '", B5, "', b'",D5,"'),") -> (10, 13, 'Physical controls', b'1'),
A6: 10 | B6: Technological controls | C6: =C5+1 -> 14 | D6: 1 | F6: =_xlfn.CONCAT("(",A6,", ",C6, ", '", B6, "', b'",D6,"'),") -> (10, 14, 'Technological controls', b'1'),
A7: 0 | B7: Asset.Primary | C7: 20 | D7: 1 | F7: =_xlfn.CONCAT("(",A7,", ",C7, ", '", B7, "', b'",D7,"'),") -> (0, 20, 'Asset.Primary', b'1'),
A8: =A6+10 -> 20 | B8: Information | C8: =C7+1 -> 21 | D8: 1 | F8: =_xlfn.CONCAT("(",A8,", ",C8, ", '", B8, "', b'",D8,"'),") -> (20, 21, 'Information', b'1'),
A9: 20 | B9: Business Process | C9: =C8+1 -> 22 | D9: 1 | F9: =_xlfn.CONCAT("(",A9,", ",C9, ", '", B9, "', b'",D9,"'),") -> (20, 22, 'Business Process', b'1'),
A10: 20 | B10: Business Activity | C10: =C9+1 -> 23 | D10: 1 | F10: =_xlfn.CONCAT("(",A10,", ",C10, ", '", B10, "', b'",D10,"'),") -> (20, 23, 'Business Activity', b'1'),
A11: 0 | B11: Asset.Supporting | C11: 30 | D11: 1 | F11: =_xlfn.CONCAT("(",A11,", ",C11, ", '", B11, "', b'",D11,"'),") -> (0, 30, 'Asset.Supporting', b'1'),
A12: =A10+10 -> 30 | B12: Hardware | C12: =C11+1 -> 31 | D12: 1 | F12: =_xlfn.CONCAT("(",A12,", ",C12, ", '", B12, "', b'",D12,"'),") -> (30, 31, 'Hardware', b'1'),
A13: 30 | B13: Software | C13: =C12+1 -> 32 | D13: 1 | F13: =_xlfn.CONCAT("(",A13,", ",C13, ", '", B13, "', b'",D13,"'),") -> (30, 32, 'Software', b'1'),
A14: 30 | B14: Network | C14: =C13+1 -> 33 | D14: 1 | F14: =_xlfn.CONCAT("(",A14,", ",C14, ", '", B14, "', b'",D14,"'),") -> (30, 33, 'Network', b'1'),
A15: 30 | B15: Personnel | C15: =C14+1 -> 34 | D15: 1 | F15: =_xlfn.CONCAT("(",A15,", ",C15, ", '", B15, "', b'",D15,"'),") -> (30, 34, 'Personnel', b'1'),
A16: 0 | B16: Control.Category | C16: 40 | D16: 1 | F16: =_xlfn.CONCAT("(",A16,", ",C16, ", '", B16, "', b'",D16,"'),") -> (0, 40, 'Control.Category', b'1'),
A17: =A15+10 -> 40 | B17: People | C17: =C16+1 -> 41 | D17: 1 | F17: =_xlfn.CONCAT("(",A17,", ",C17, ", '", B17, "', b'",D17,"'),") -> (40, 41, 'People', b'1'),
A18: 40 | B18: Physical | C18: =C17+1 -> 42 | D18: 1 | F18: =_xlfn.CONCAT("(",A18,", ",C18, ", '", B18, "', b'",D18,"'),") -> (40, 42, 'Physical', b'1'),
A19: 40 | B19: Technological | C19: =C18+1 -> 43 | D19: 1 | F19: =_xlfn.CONCAT("(",A19,", ",C19, ", '", B19, "', b'",D19,"'),") -> (40, 43, 'Technological', b'1'),
A20: 40 | B20: Otherwise | C20: =C19+1 -> 44 | D20: 1 | F20: =_xlfn.CONCAT("(",A20,", ",C20, ", '", B20, "', b'",D20,"'),") -> (40, 44, 'Otherwise', b'1'),
A21: 0 | B21: Organization.ControlType | C21: 50 | D21: 1 | F21: =_xlfn.CONCAT("(",A21,", ",C21, ", '", B21, "', b'",D21,"'),") -> (0, 50, 'Organization.ControlType', b'1'),
A22: =A20+10 -> 50 | B22: Preventive | C22: =C21+1 -> 51 | D22: 1 | F22: =_xlfn.CONCAT("(",A22,", ",C22, ", '", B22, "', b'",D22,"'),") -> (50, 51, 'Preventive', b'1'),
A23: 50 | B23: Detective | C23: =C22+1 -> 52 | D23: 1 | F23: =_xlfn.CONCAT("(",A23,", ",C23, ", '", B23, "', b'",D23,"'),") -> (50, 52, 'Detective', b'1'),
A24: 50 | B24: Corrective | C24: =C23+1 -> 53 | D24: 1 | F24: =_xlfn.CONCAT("(",A24,", ",C24, ", '", B24, "', b'",D24,"'),") -> (50, 53, 'Corrective', b'1'),
A25: 0 | B25: Information.Security.Property | C25: 60 | D25: 1 | F25: =_xlfn.CONCAT("(",A25,", ",C25, ", '", B25, "', b'",D25,"'),") -> (0, 60, 'Information.Security.Property', b'1'),
A26: =A24+10 -> 60 | B26: Confidentiality | C26: =C25+1 -> 61 | D26: 1 | F26: =_xlfn.CONCAT("(",A26,", ",C26, ", '", B26, "', b'",D26,"'),") -> (60, 61, 'Confidentiality', b'1'),
A27: 60 | B27: Integrity | C27: =C26+1 -> 62 | D27: 1 | F27: =_xlfn.CONCAT("(",A27,", ",C27, ", '", B27, "', b'",D27,"'),") -> (60, 62, 'Integrity', b'1'),
A28: 60 | B28: Availability | C28: =C27+1 -> 63 | D28: 1 | F28: =_xlfn.CONCAT("(",A28,", ",C28, ", '", B28, "', b'",D28,"'),") -> (60, 63, 'Availability', b'1'),
A29: 0 | B29: Cybersecurity.Concept | C29: 70 | D29: 1 | F29: =_xlfn.CONCAT("(",A29,", ",C29, ", '", B29, "', b'",D29,"'),") -> (0, 70, 'Cybersecurity.Concept', b'1'),
A30: =A28+10 -> 70 | B30: Identify | C30: =C29+1 -> 71 | D30: 1 | F30: =_xlfn.CONCAT("(",A30,", ",C30, ", '", B30, "', b'",D30,"'),") -> (70, 71, 'Identify', b'1'),
A31: 70 | B31: Protect | C31: =C30+1 -> 72 | D31: 1 | F31: =_xlfn.CONCAT("(",A31,", ",C31, ", '", B31, "', b'",D31,"'),") -> (70, 72, 'Protect', b'1'),
A32: 70 | B32: Detect | C32: =C31+1 -> 73 | D32: 1 | F32: =_xlfn.CONCAT("(",A32,", ",C32, ", '", B32, "', b'",D32,"'),") -> (70, 73, 'Detect', b'1'),
A33: 70 | B33: Respond | C33: =C32+1 -> 74 | D33: 1 | F33: =_xlfn.CONCAT("(",A33,", ",C33, ", '", B33, "', b'",D33,"'),") -> (70, 74, 'Respond', b'1'),
A34: 70 | B34: Recover | C34: =C33+1 -> 75 | D34: 1 | F34: =_xlfn.CONCAT("(",A34,", ",C34, ", '", B34, "', b'",D34,"'),") -> (70, 75, 'Recover', b'1'),
A35: 0 | B35: Security.Domain | C35: 80 | D35: 1 | F35: =_xlfn.CONCAT("(",A35,", ",C35, ", '", B35, "', b'",D35,"'),") -> (0, 80, 'Security.Domain', b'1'),
A36: =A34+10 -> 80 | B36: Governance and Ecosystem | C36: =C35+1 -> 81 | D36: 1 | F36: =_xlfn.CONCAT("(",A36,", ",C36, ", '", B36, "', b'",D36,"'),") -> (80, 81, 'Governance and Ecosystem', b'1'),
A37: 80 | B37: Protection | C37: =C36+1 -> 82 | D37: 1 | F37: =_xlfn.CONCAT("(",A37,", ",C37, ", '", B37, "', b'",D37,"'),") -> (80, 82, 'Protection', b'1'),
A38: 80 | B38: Defence | C38: =C37+1 -> 83 | D38: 1 | F38: =_xlfn.CONCAT("(",A38,", ",C38, ", '", B38, "', b'",D38,"'),") -> (80, 83, 'Defence', b'1'),
A39: 80 | B39: Resilience | C39: =C38+1 -> 84 | D39: 1 | F39: =_xlfn.CONCAT("(",A39,", ",C39, ", '", B39, "', b'",D39,"'),") -> (80, 84, 'Resilience', b'1'),
A40: 0 | B40: Operational.Capabilities | C40: 100 | D40: 1 | F40: =_xlfn.CONCAT("(",A40,", ",C40, ", '", B40, "', b'",D40,"'),") -> (0, 100, 'Operational.Capabilities', b'1'),
...

Sheet Tables
A1: Table | B1: Organization.Policy | M1: INSERT INTO asjrf517_ozorasoft_infoseccontrols.OrganizationPolicy
A2: Id | B2: Code | C2: ControlName | D2: Information.Security.ControlID | E2: Id | F2: ControlType | G2: InformationSecurityProperties | H2: CyberSecurityConcepts | I2: OperationalCapabilities | J2: SecurityDomains | K2: Active | M2: (code, name, information_security_control_id, control_type, information_security_properties, cybersecurity_concepts, operational_capabilities, security_domains, active) VALUES
A3: 1 | B3: 5.1 | C3: Policies for information security | D3: Organizational controls | E3: =VLOOKUP(D3,Enums!$B$2:$C$55, 2,FALSE) -> 11 | F3: Preventive | G3: Confidentiality, Integrity, Availability | H3: Identify | I3: Governance | J3: Governance_and_Ecosystem,Resilience | K3: TRUE | M3: =_xlfn.CONCAT("('",B3,"', '",C3,"', ",E3,", JSON_ARRAY('",F3,"'), JSON_ARRAY('",G3,"'), JSON_ARRAY('",H3,"'), JSON_ARRAY('",I3,"'), JSON_ARRAY('",J3,"'), b'1'),") -> ('5.1', 'Policies for information security', 11, JSON_ARRAY('Preventive'), JSON_ARRAY('Confidentiality, Integrity, Availability'), JSON_ARRAY('Identify'), JSON_ARRAY('Governance'), JSON_ARRAY('Governance_and_Ecosystem,Resilience'), b'1'),
A4: 2 | B4: 5.2 | C4: Information security roles and responsibilities | D4: Organizational controls | E4: =VLOOKUP(D4,Enums!$B$2:$C$55, 2,FALSE) -> 11 | F4: Preventive | G4: Confidentiality, Integrity, Availability | H4: Identify | I4: Governance | J4: Governance_and_Ecosystem,Protection,Resilience | K4: TRUE | M4: =_xlfn.CONCAT("('",B4,"', '",C4,"', ",E4,", JSON_ARRAY('",F4,"'), JSON_ARRAY('",G4,"'), JSON_ARRAY('",H4,"'), JSON_ARRAY('",I4,"'), JSON_ARRAY('",J4,"'), b'1'),") -> ('5.2', 'Information security roles and responsibilities', 11, JSON_ARRAY('Preventive'), JSON_ARRAY('Confidentiality, Integrity, Availability'), JSON_ARRAY('Identify'), JSON_ARRAY('Governance'), JSON_ARRAY('Governance_and_Ecosystem,Protection,Resilience'), b'1'),
A5: 3 | B5: 5.3 | C5: Segregation of duties | D5: Organizational controls | E5: =VLOOKUP(D5,Enums!$B$2:$C$55, 2,FALSE) -> 11 | F5: Preventive | G5: Confidentiality, Integrity, Availability | H5: Protect | I5: Governance,Identity_and_access_management | J5: Governance | K5: TRUE | M5: =_xlfn.CONCAT("('",B5,"', '",C5,"', ",E5,", JSON_ARRAY('",F5,"'), JSON_ARRAY('",G5,"'), JSON_ARRAY('",H5,"'), JSON_ARRAY('",I5,"'), JSON_ARRAY('",J5,"'), b'1'),") -> ('5.3', 'Segregation of duties', 11, JSON_ARRAY('Preventive'), JSON_ARRAY('Confidentiality, Integrity, Availability'), JSON_ARRAY('Protect'), JSON_ARRAY('Governance,Identity_and_access_management'), JSON_ARRAY('Governance'), b'1'),
A6: 4 | B6: 5.4 | C6: Management responsibilities | D6: Organizational controls | E6: =VLOOKUP(D6,Enums!$B$2:$C$55, 2,FALSE) -> 11 | F6: Preventive | G6: Confidentiality, Integrity, Availability | H6: Identify | I6: Governance | J6: Governance_and_Ecosystem | K6: TRUE | M6: =_xlfn.CONCAT("('",B6,"', '",C6,"', ",E6,", JSON_ARRAY('",F6,"'), JSON_ARRAY('",G6,"'), JSON_ARRAY('",H6,"'), JSON_ARRAY('",I6,"'), JSON_ARRAY('",J6,"'), b'1'),") -> ('5.4', 'Management responsibilities', 11, JSON_ARRAY('Preventive'), JSON_ARRAY('Confidentiality, Integrity, Availability'), JSON_ARRAY('Identify'), JSON_ARRAY('Governance'), JSON_ARRAY('Governance_and_Ecosystem'), b'1'),
A7: 5 | B7: 5.5 | C7: Contact with authorities | D7: Organizational controls | E7: =VLOOKUP(D7,Enums!$B$2:$C$55, 2,FALSE) -> 11 | F7: Preventive,Corrective | G7: Confidentiality, Integrity, Availability | H7: Identify,Protect,Respond,Recover | I7: Governance | J7: Defence,Resilience | K7: TRUE | M7: =_xlfn.CONCAT("('",B7,"', '",C7,"', ",E7,", JSON_ARRAY('",F7,"'), JSON_ARRAY('",G7,"'), JSON_ARRAY('",H7,"'), JSON_ARRAY('",I7,"'), JSON_ARRAY('",J7,"'), b'1'),") -> ('5.5', 'Contact with authorities', 11, JSON_ARRAY('Preventive,Corrective'), JSON_ARRAY('Confidentiality, Integrity, Availability'), JSON_ARRAY('Identify,Protect,Respond,Recover'), JSON_ARRAY('Governance'), JSON_ARRAY('Defence,Resilience'), b'1'),
A8: 6 | B8: 5.6 | C8: Contact with special interest groups | D8: Organizational controls | E8: =VLOOKUP(D8,Enums!$B$2:$C$55, 2,FALSE) -> 11 | F8: Preventive,Corrective | G8: Confidentiality, Integrity, Availability | H8: Protect,Respond,Recover | I8: Governance | J8: Defence | K8: TRUE | M8: =_xlfn.CONCAT("('",B8,"', '",C8,"', ",E8,", JSON_ARRAY('",F8,"'), JSON_ARRAY('",G8,"'), JSON_ARRAY('",H8,"'), JSON_ARRAY('",I8,"'), JSON_ARRAY('",J8,"'), b'1'),") -> ('5.6', 'Contact with special interest groups', 11, JSON_ARRAY('Preventive,Corrective'), JSON_ARRAY('Confidentiality, Integrity, Availability'), JSON_ARRAY('Protect,Respond,Recover'), JSON_ARRAY('Governance'), JSON_ARRAY('Defence'), b'1'),
A9: 7 | B9: 5.7 | C9: Threat intelligence | D9: Organizational controls | E9: =VLOOKUP(D9,Enums!$B$2:$C$55, 2,FALSE) -> 11 | F9: Preventive,Detective,Corrective | G9: Confidentiality, Integrity, Availability | H9: Identify,Detect,Respond | I9: Threat_and_vulnerability_management | J9: Defence,Resilience | K9: TRUE | M9: =_xlfn.CONCAT("('",B9,"', '",C9,"', ",E9,", JSON_ARRAY('",F9,"'), JSON_ARRAY('",G9,"'), JSON_ARRAY('",H9,"'), JSON_ARRAY('",I9,"'), JSON_ARRAY('",J9,"'), b'1'),") -> ('5.7', 'Threat intelligence', 11, JSON_ARRAY('Preventive,Detective,Corrective'), JSON_ARRAY('Confidentiality, Integrity, Availability'), JSON_ARRAY('Identify,Detect,Respond'), JSON_ARRAY('Threat_and_vulnerability_management'), JSON_ARRAY('Defence,Resilience'), b'1'),
A10: 8 | B10: 5.8 | C10: Information security in project management | D10: Organizational controls | E10: =VLOOKUP(D10,Enums!$B$2:$C$55, 2,FALSE) -> 11 | F10: Preventive | G10: Confidentiality, Integrity, Availability | H10: Identify,Protect | I10: Governance | J10: Governance_and_EcosystemProtection | K10: TRUE | M10: =_xlfn.CONCAT("('",B10,"', '",C10,"', ",E10,", JSON_ARRAY('",F10,"'), JSON_ARRAY('",G10,"'), JSON_ARRAY('",H10,"'), JSON_ARRAY('",I10,"'), JSON_ARRAY('",J10,"'), b'1'),") -> ('5.8', 'Information security in project management', 11, JSON_ARRAY('Preventive'), JSON_ARRAY('Confidentiality, Integrity, Availability'), JSON_ARRAY('Identify,Protect'), JSON_ARRAY('Governance'), JSON_ARRAY('Governance_and_EcosystemProtection'), b'1'),
A11: 9 | B11: 5.9 | C11: Inventory of information and other associated assets | D11: Organizational controls | E11: =VLOOKUP(D11,Enums!$B$2:$C$55, 2,FALSE) -> 11 | F11: Preventive | G11: Confidentiality, Integrity, Availability | H11: Identify | I11: Asset_management | J11: Governance_and_Ecosystem,Protection | K11: TRUE | M11: =_xlfn.CONCAT("('",B11,"', '",C11,"', ",E11,", JSON_ARRAY('",F11,"'), JSON_ARRAY('",G11,"'), JSON_ARRAY('",H11,"'), JSON_ARRAY('",I11,"'), JSON_ARRAY('",J11,"'), b'1'),") -> ('5.9', 'Inventory of information and other associated assets', 11, JSON_ARRAY('Preventive'), JSON_ARRAY('Confidentiality, Integrity, Availability'), JSON_ARRAY('Identify'), JSON_ARRAY('Asset_management'), JSON_ARRAY('Governance_and_Ecosystem,Protection'), b'1'),
A12: 10 | B12: 5.10 | C12: Acceptable use of information and other associated assets | D12: Organizational controls | E12: =VLOOKUP(D12,Enums!$B$2:$C$55, 2,FALSE) -> 11 | F12: Preventive | G12: Confidentiality, Integrity, Availability | H12: Protect | I12: Asset_management,Information_protection | J12: Governance_and_Ecosystem,Protection | K12: TRUE | M12: =_xlfn.CONCAT("('",B12,"', '",C12,"', ",E12,", JSON_ARRAY('",F12,"'), JSON_ARRAY('",G12,"'), JSON_ARRAY('",H12,"'), JSON_ARRAY('",I12,"'), JSON_ARRAY('",J12,"'), b'1'),") -> ('5.10', 'Acceptable use of information and other associated assets', 11, JSON_ARRAY('Preventive'), JSON_ARRAY('Confidentiality, Integrity, Availability'), JSON_ARRAY('Protect'), JSON_ARRAY('Asset_management,Information_protection'), JSON_ARRAY('Governance_and_Ecosystem,Protection'), b'1'),
A13: 11 | B13: 5.11 | C13: Return of assets | D13: Organizational controls | E13: =VLOOKUP(D13,Enums!$B$2:$C$55, 2,FALSE) -> 11 | F13: Preventive | G13: Confidentiality, Integrity, Availability | H13: Protect | I13: Asset_management | J13: Protection | K13: TRUE | M13: =_xlfn.CONCAT("('",B13,"', '",C13,"', ",E13,", JSON_ARRAY('",F13,"'), JSON_ARRAY('",G13,"'), JSON_ARRAY('",H13,"'), JSON_ARRAY('",I13,"'), JSON_ARRAY('",J13,"'), b'1'),") -> ('5.11', 'Return of assets', 11, JSON_ARRAY('Preventive'), JSON_ARRAY('Confidentiality, Integrity, Availability'), JSON_ARRAY('Protect'), JSON_ARRAY('Asset_management'), JSON_ARRAY('Protection'), b'1'),
A14: 12 | B14: 5.12 | C14: Classification of information | D14: Organizational controls | E14: =VLOOKUP(D14,Enums!$B$2:$C$55, 2,FALSE) -> 11 | F14: Preventive | G14: Confidentiality, Integrity, Availability | H14: Identify | I14: Information_protection | J14: Protection,Defence | K14: TRUE | M14: =_xlfn.CONCAT("('",B14,"', '",C14,"', ",E14,", JSON_ARRAY('",F14,"'), JSON_ARRAY('",G14,"'), JSON_ARRAY('",H14,"'), JSON_ARRAY('",I14,"'), JSON_ARRAY('",J14,"'), b'1'),") -> ('5.12', 'Classification of information', 11, JSON_ARRAY('Preventive'), JSON_ARRAY('Confidentiality, Integrity, Availability'), JSON_ARRAY('Identify'), JSON_ARRAY('Information_protection'), JSON_ARRAY('Protection,Defence'), b'1'),
... A95: 93 | B95: 8.34 | C95: Protection of information systems during audit testing | D95: Technological controls | E95: =VLOOKUP(D95,Enums!$B$2:$C$55, 2,FALSE) -> 14 | F95: Preventive | G95: Confidentiality, Integrity, Availability | H95: Protect | I95: System_and_network_security,Information_protection | J95: Governance_and_Ecosystem,Protection | K95: TRUE | M95: =_xlfn.CONCAT("('",B95,"', '",C95,"', ",E95,", JSON_ARRAY('",F95,"'), JSON_ARRAY('",G95,"'), JSON_ARRAY('",H95,"'), JSON_ARRAY('",I95,"'), JSON_ARRAY('",J95,"'), b'1'),") -> ('8.34', 'Protection of information systems during audit testing', 14, JSON_ARRAY('Preventive'), JSON_ARRAY('Confidentiality, Integrity, Availability'), JSON_ARRAY('Protect'), JSON_ARRAY('System_and_network_security,Information_protection'), JSON_ARRAY('Governance_and_Ecosystem,Protection'), b'1'),

Sheet Abbreviatures
A1: Abbreviated terms
A2: ABAC attribute-based access control
A3: ACL access control list
A4: BIA business impact analysis
A5: BYOD bring your own device
A6: CAPTCHA completely automated public Turing test to tell computers and humans apart
A7: CPU central processing unit
A8: DAC discretionary access control
A9: DNS domain name system
A10: GPS global positioning system
A11: IAM identity and access management
A12: ICT information and communication technology
... A46: WiFi wireless fidelity
